<?xml version="1.0" ?>
<robot name="m0609">

  <material name="black">
    <color rgba="0.0 0.0 0.0 1.0"/>
  </material>
  <material name="white">
    <color rgba="1.0 1.0 1.0 1.0"/>
  </material>
  <material name="orange">
    <color rgba="1.0 0.4 0.0 1.0"/>
  </material>

  <material name="dr_gray">
    <color rgba="0.490 0.490 0.486 1.0"/>
  </material>
  <material name="dr_white">
    <color rgba="0.941 0.941 0.941 1.0"/>
  </material>
  
  <!-- <link name="base"/>
  <joint name="fixed" type="fixed">
    <parent link="base"/>
    <child link="base_0"/>
  </joint> -->
  
  <link name="base_0">
	<inertial>
	  <mass value="3.722"/>
	  <origin xyz="-1.2e-05 -6e-05 0.00"/>
      <inertia ixx="0.011" ixy="-7.19e-06" ixz="-1.94e-06" iyy="0.011" iyz="4.9e-06" izz="0.014"/>
    </inertial>
	<visual>
      <origin rpy="0 0 0" xyz="0 0 0"/>
      <geometry>
        <mesh filename="package://dsr_description/meshes/m0609/MF0609_0_0.dae" scale="0.001 0.001 0.001"/>
      </geometry>
      <material name="dr_gray"/>
    </visual>
  </link>

  <joint name="joint1" type="revolute">
    <parent link="base_0"/>
    <child link="link1"/>
    <origin rpy="0 0 0" xyz="0 0 0.135"/>
    <axis xyz="0 0 1"/>
    <limit effort="30" lower="-2.617" upper="2.617" velocity="1.5708"/>
  </joint>

  <link name="link1">
	<inertial>
	  <mass value="4.935"/>
	  <origin xyz="0.000068 0.036439 -0.005709"/>
      <inertia ixx="0.018" ixy="1.52e-05" ixz="-2.29e-05" iyy="0.011" iyz="-0.001" izz="0.019"/>
    </inertial>
    <visual>
      <origin rpy="0 0 0" xyz="0 0 0"/>
      <geometry>
        <mesh filename="package://dsr_description/meshes/m0609/MF0609_1_0.dae" scale="0.001 0.001 0.001"/>
      </geometry>
      <material name="dr_white"/>
    </visual>
  </link>
  
  <joint name="joint2" type="revolute">
    <parent link="link1"/>
    <child link="link2"/>
    <origin rpy="0 -1.5708 -1.5708" xyz="0 0.0062 0"/>
    <axis xyz="0 0 1"/>
    <limit effort="30" lower="-2.617" upper="2.617" velocity="1.5708"/>
  </joint>

  <link name="link2">
	<inertial>
	  <mass value="8.363"/>
	  <origin xyz="0.205144 0.000003 0.15744"/>
      <inertia ixx="0.292" ixy="-7.78e-07" ixz="-0.000151" iyy="0.293" iyz="-0.000297" izz="0.021"/>
    </inertial>
    <visual>
      <origin rpy="0 0 0" xyz="0 0 0"/>
      <geometry>
        <mesh filename="package://dsr_description/meshes/m0609/MF0609_2_0.dae" scale="0.001 0.001 0.001"/>
      </geometry>
      <material name="dr_white"/>
    </visual>
    <visual>
      <origin rpy="0 0 0" xyz="0 0 0"/>
      <geometry>     
		<mesh filename="package://dsr_description/meshes/m0609/MF0609_2_1.dae" scale="0.001 0.001 0.001"/>
      </geometry>
      <material name="dr_gray">
        <color rgba="0.490 0.490 0.486 1.0"/>
      </material>
	  </visual>
    <visual>
      <origin rpy="0 0 0" xyz="0 0 0"/>
      <geometry>     
		<mesh filename="package://dsr_description/meshes/m0609/MF0609_2_2.dae" scale="0.001 0.001 0.001"/>
      </geometry>
      <material name="dr_white"/>
    </visual>	
  </link>

  <joint name="joint3" type="revolute">
    <parent link="link2"/>
    <child link="link3"/>
    <origin rpy="0 0 1.5708" xyz="0.411 0 0"/>
    <axis xyz="0 0 1"/>
    <limit effort="30" lower="-2.617" upper="2.617" velocity="1.5708"/>
  </joint>
  
  <link name="link3">
	<inertial>
	  <mass value="3.583"/>
	  <origin xyz="-0.000007 -0.009445 0.044429"/>
      <inertia ixx="0.012" ixy="-4.16e-06" ixz="-1.27e-06" iyy="0.007" iyz="0.002" izz="0.011"/>
    </inertial>
    <visual>
      <origin rpy="0 0 0" xyz="0 0 0"/>
      <geometry>     
		<mesh filename="package://dsr_description/meshes/m0609/MF0609_3_0.dae" scale="0.001 0.001 0.001"/>
      </geometry>
      <material name="dr_white"/>
    </visual>
  </link>

  <joint name="joint4" type="revolute">
    <parent link="link3"/>
    <child link="link4"/>
    <origin rpy="1.5708 0 0" xyz="0 -0.368 0"/>
    <axis xyz="0 0 1"/>
    <limit effort="30" lower="-2.617" upper="2.617" velocity="1.5708"/>
  </joint>
  
  <link name="link4">
	<inertial>
	  <mass value="3.433"/>
	  <origin xyz="0.000009 0.123291 -0.108502"/>
      <inertia ixx="0.07" ixy="-1.34e-05" ixz="-1.19e-05" iyy="0.056" iyz="-0.026" izz="0.019"/>
    </inertial>
    <visual>
      <origin rpy="0 0 0" xyz="0 0 0"/>
      <geometry>     
		<mesh filename="package://dsr_description/meshes/m0609/MF0609_4_0.dae" scale="0.001 0.001 0.001"/>
      </geometry>
      <material name="dr_white"/>
    </visual>
    <visual>
      <origin rpy="0 0 0" xyz="0 0 0"/>
      <geometry>     
		<mesh filename="package://dsr_description/meshes/m0609/MF0609_4_1.dae" scale="0.001 0.001 0.001"/>
      </geometry>
      <material name="dr_white">
        <color rgba="0.941 0.941 0.941 1.0"/>
      </material>
    </visual>
  </link>

  <joint name="joint5" type="revolute">
    <parent link="link4"/>
    <child link="link5"/>
    <origin rpy="-1.5708 0 0" xyz="0 0 0"/>
    <axis xyz="0 0 1"/>
    <limit effort="30" lower="-2.617" upper="2.617" velocity="1.5708"/>
  </joint>
  
  <link name="link5">
	<inertial>
	  <mass value="2.598"/>
	  <origin xyz="-0.000015 0.000472 0.032121"/>
      <inertia ixx="0.007" ixy="-4.93e-06" ixz="-5.57e-06" iyy="0.004" iyz="-6.64e-05" izz="0.007"/>
    </inertial>
    <visual>
      <origin rpy="0 0 0" xyz="0 0 0"/>
      <geometry>     
		<mesh filename="package://dsr_description/meshes/m0609/MF0609_5_0.dae" scale="0.001 0.001 0.001"/>
      </geometry>
      <material name="dr_white"/>
    </visual>
  </link>

  <joint name="joint6" type="revolute">
    <parent link="link5"/>
    <child link="link6"/>
    <origin rpy="1.5708 0 0" xyz="0 -0.121 0"/>
    <axis xyz="0 0 1"/>
    <limit effort="30" lower="-2.617" upper="2.617" velocity="1.5708"/>
  </joint>
  
  <link name="link6">
	<inertial>
	  <mass value="3.138"/>
	  <origin xyz="-0.000061827915870   0.000075487571702   0.013234676864245"/>
      <inertia ixx="0.001" ixy="-2.79e-06" ixz="5.78e-06" iyy="0.001" iyz="-6.67e-06" izz="0.001"/>
    </inertial>
    <visual>
      <origin rpy="0 0 0" xyz="0 0 0"/>
      <geometry>     
		<mesh filename="package://dsr_description/meshes/m0609/MF0609_6_0.dae" scale="0.001 0.001 0.001"/>
      </geometry>
      <material name="dr_gray"/>
    </visual>
  </link>
  
</robot>
